<?xml version="1.0" ?>
<!-- =================================================================================== -->
<!-- |    This document was autogenerated by xacro from agvs.urdf.xacro                | -->
<!-- |    EDITING THIS FILE BY HAND IS NOT RECOMMENDED                                 | -->
<!-- =================================================================================== -->
<robot name="agvs" xmlns:xacro="http://www.ros.org/wiki/xacro">
  <!-- Import all Gazebo-customization elements, including Gazebo colors -->
  <gazebo>
    <plugin filename="libgazebo_ros_control.so" name="ros_control">
      <robotNamespace>/agvs</robotNamespace>
      <controlPeriod>0.001</controlPeriod>
      <robotSimType>gazebo_ros_control/DefaultRobotHWSim</robotSimType>
    </plugin>
  </gazebo>
  <gazebo reference="base_footprint">
    <material>Gazebo/Green</material>
  </gazebo>
  <gazebo reference="base_link">
    <material>Gazebo/Red</material>
  </gazebo>
  <gazebo reference="back_left_wheel">
    <mu1 value="4.0"/>
    <!-- 2.0 -->
    <mu2 value="1.0"/>
    <!-- 0.5 -->
    <fdir1 value="1 0 0"/>
    <material>Gazebo/Grey</material>
  </gazebo>
  <gazebo reference="back_right_wheel">
    <mu1 value="4.0"/>
    <!-- 2.0 -->
    <mu2 value="1.0"/>
    <!-- 0.5 -->
    <fdir1 value="1 0 0"/>
    <material>Gazebo/Grey</material>
  </gazebo>
  <gazebo reference="front_left_wheel">
    <mu1 value="4.0"/>
    <!-- 2.0 -->
    <mu2 value="1.0"/>
    <!-- 0.5 -->
    <fdir1 value="1 0 0"/>
    <material>Gazebo/Grey</material>
  </gazebo>
  <gazebo reference="front_right_wheel">
    <mu1 value="4.0"/>
    <!-- 2.0 -->
    <mu2 value="1.0"/>
    <!-- 0.5 -->
    <fdir1 value="1 0 0"/>
    <material>Gazebo/Grey</material>
  </gazebo>
  <gazebo reference="camera_tilt_link">
    <mu1>0.2</mu1>
    <mu2>0.2</mu2>
    <material>Gazebo/Red</material>
    <sensor name="camera1" type="camera">
      <update_rate>30.0</update_rate>
      <camera name="head">
        <horizontal_fov>1.3962634</horizontal_fov>
        <image>
          <width>800</width>
          <height>800</height>
          <format>R8G8B8</format>
        </image>
        <clip>
          <near>0.02</near>
          <far>300</far>
        </clip>
        <noise>
          <type>gaussian</type>
          <!-- Noise is sampled independently per pixel on each frame.  
               That pixel's noise value is added to each of its color
               channels, which at that point lie in the range [0,1]. -->
          <mean>0.0</mean>
          <stddev>0.007</stddev>
        </noise>
      </camera>
      <plugin filename="libgazebo_ros_camera.so" name="camera_controller">
        <alwaysOn>true</alwaysOn>
        <updateRate>0.0</updateRate>
        <cameraName>/agvs/camera1</cameraName>
        <imageTopicName>image_raw</imageTopicName>
        <cameraInfoTopicName>camera_info</cameraInfoTopicName>
        <frameName>camera_tilt_link</frameName>
        <hackBaseline>0.07</hackBaseline>
        <distortionK1>0.0</distortionK1>
        <distortionK2>0.0</distortionK2>
        <distortionK3>0.0</distortionK3>
        <distortionT1>0.0</distortionT1>
        <distortionT2>0.0</distortionT2>
      </plugin>
    </sensor>
  </gazebo>
  <gazebo reference="hokuyo_laser_link">
    <!-- sensor type="gpu_ray" name="head_hokuyo_sensor" -->
    <sensor name="head_hokuyo_sensor" type="ray">
      <pose>0 0 0 0 0 0</pose>
      <visualize>false</visualize>
      <update_rate>30</update_rate>
      <ray>
        <scan>
          <horizontal>
            <!-- samples>720</samples>
            <resolution>1</resolution>
            <min_angle>-1.570796</min_angle>
            <max_angle>1.570796</max_angle -->
            <samples>1081</samples>
            <resolution>1</resolution>
            <min_angle>2.35619449</min_angle>
            <!-- +/-135 deg -->
            <max_angle>-2.35619449</max_angle>
          </horizontal>
        </scan>
        <range>
          <min>0.10</min>
          <max>30.0</max>
          <resolution>0.01</resolution>
        </range>
        <noise>
          <type>gaussian</type>
          <mean>0.0</mean>
          <stddev>0.01</stddev>
        </noise>
      </ray>
      <!-- plugin name="gazebo_ros_head_hokuyo_controller" filename="libgazebo_ros_gpu_laser.so" -->
      <plugin filename="libgazebo_ros_laser.so" name="gazebo_ros_head_hokuyo_controller">
        <topicName>/scan</topicName>
        <frameName>hokuyo_laser_link</frameName>
      </plugin>
    </sensor>
  </gazebo>
  <gazebo>
    <plugin filename="libgazebo_ros_imu.so" name="ros_imu">
      <robotNamespace>/agvs</robotNamespace>
      <topicName>imu_data</topicName>
      <bodyName>imu_link </bodyName>
      <serviceName>/imu_service</serviceName>
      <gaussianNoise>0.005</gaussianNoise>
    </plugin>
  </gazebo>
  <!-- Robot mechanical and motor parameters -->
  <!-- x,y,z in base_footprint CS -->
  <!-- Used for fixing robot to Gazebo 'base_link' -->
  <!-- link name="world"/>
  <joint name="fwf" type="planar">
    <parent link="world"/>
    <child link="base_footprint"/>
  </joint -->
  <!-- BASE FOOTPRINT -->
  <!-- base_footprint is a fictitious link(frame) that is on the ground right below base_link origin,
             navigation stack depends on this frame -->
  <link name="base_footprint">
    <visual>
      <origin rpy="0 0 0" xyz="0 0 0"/>
      <geometry>
        <box size="0.001 0.001 0.001"/>
      </geometry>
    </visual>
    <collision>
      <origin rpy="0 0 0" xyz="0 0 0"/>
      <geometry>
        <box size="0.001 0.001 0.001"/>
      </geometry>
    </collision>
  </link>
  <joint name="base_footprint_joint" type="fixed">
    <!-- NB While you would think this would make it go up, it is oddly reversed.
      This moves the joint to 0,0,0 where we want it for rviz, etc. -->
    <origin rpy="0 0 0" xyz="0 0 0"/>
    <parent link="base_footprint"/>
    <child link="base_link"/>
  </joint>
  <!-- BASE_LINK (RED) -->
  <link name="base_link">
    <inertial>
      <mass value="25.0"/>
      <origin xyz="0 0 0"/>
      <inertia ixx="1.391" ixy="0.004" ixz="0.0" iyy="6.853" iyz="0.0" izz="6.125"/>
    </inertial>
    <visual>
      <origin rpy="0 0 0" xyz="0 0 0"/>
      <geometry>
        <mesh filename="package://agvs_description/meshes/chassis_agvs.dae"/>
      </geometry>
      <material name="red">
        <color rgba="1.0 0.1 0.1 1"/>
      </material>
    </visual>
    <collision>
      <origin rpy="0 0 0 " xyz="0 0 0"/>
      <geometry>
        <mesh filename="package://agvs_description/meshes/chassis_agvs.dae"/>
      </geometry>
    </collision>
  </link>
  <!-- BACK MOTOR WHEEL (GREY) -->
  <link name="back_motor_wheel">
    <inertial>
      <mass value="1.250"/>
      <origin xyz="0 0 0"/>
      <inertia ixx="0.0109375" ixy="0.0" ixz="0.0" iyy="0.021125" iyz="0.0" izz="0.0109375"/>
    </inertial>
    <visual>
      <origin rpy="0 0 0" xyz="0 0 0"/>
      <geometry>
        <mesh filename="package://agvs_description/meshes/motor_wheel.dae" scale="1.0 1.0 1.0"/>
      </geometry>
      <material name="grey">
        <color rgba="0.5 0.5 0.5 1"/>
      </material>
    </visual>
    <collision>
      <origin rpy="0 0 0" xyz="0 0 0"/>
      <geometry>
        <mesh filename="package://agvs_description/meshes/motor_wheel.dae" scale="1.0 1.0 1.0"/>
      </geometry>
    </collision>
  </link>
  <joint name="joint_back_motor_wheel" type="continuous">
    <parent link="base_link"/>
    <child link="back_motor_wheel"/>
    <origin rpy="0 0 0" xyz="-0.479 0.0 0.11"/>
    <axis rpy="0 0 0" xyz="0 0 1"/>
    <limit effort="100.0" velocity="100.0"/>
    <joint_properties damping="0.0" friction="{wheel_joint_friction}"/>
  </joint>
  <transmission name="joint_bmw_trans">
    <type>transmission_interface/SimpleTransmission</type>
    <joint name="joint_back_motor_wheel"/>
    <actuator name="joint_bmw_motor">
      <hardwareInterface>EffortJointInterface</hardwareInterface>
      <mechanicalReduction>1.0</mechanicalReduction>
    </actuator>
  </transmission>
  <!-- BACK WHEEL (GREY) -->
  <link name="back_wheel">
    <inertial>
      <mass value="1.250"/>
      <origin xyz="0 0 0"/>
      <inertia ixx="0.0109375" ixy="0.0" ixz="0.0" iyy="0.021125" iyz="0.0" izz="0.0109375"/>
    </inertial>
    <visual>
      <origin rpy="0 0 0" xyz="0 0 0"/>
      <geometry>
        <mesh filename="package://agvs_description/meshes/agvs_wheel.dae" scale="1.0 1.0 1.0"/>
      </geometry>
      <material name="grey">
        <color rgba="0.5 0.5 0.5 1"/>
      </material>
    </visual>
    <collision>
      <origin rpy="0 0 0" xyz="0 0 0"/>
      <geometry>
        <mesh filename="package://agvs_description/meshes/agvs_wheel.dae" scale="1.0 1.0 1.0"/>
      </geometry>
    </collision>
  </link>
  <joint name="joint_back_wheel" type="continuous">
    <parent link="back_motor_wheel"/>
    <child link="back_wheel"/>
    <origin rpy="0 0 3.1416" xyz="0 0 0"/>
    <axis rpy="0 0 0" xyz="0 1 0"/>
    <limit effort="100.0" velocity="100.0"/>
    <joint_properties damping="0.0" friction="{wheel_joint_friction}"/>
  </joint>
  <transmission name="joint_bw_trans">
    <type>transmission_interface/SimpleTransmission</type>
    <joint name="joint_back_wheel"/>
    <actuator name="joint_bw_motor">
      <hardwareInterface>EffortJointInterface</hardwareInterface>
      <mechanicalReduction>1.0</mechanicalReduction>
    </actuator>
  </transmission>
  <!-- FRONT MOTOR WHEEL (GREY) -->
  <link name="front_motor_wheel">
    <inertial>
      <mass value="1.250"/>
      <origin xyz="0 0 0"/>
      <inertia ixx="0.0109375" ixy="0.0" ixz="0.0" iyy="0.021125" iyz="0.0" izz="0.0109375"/>
    </inertial>
    <visual>
      <origin rpy="0 0 0" xyz="0 0 0"/>
      <geometry>
        <mesh filename="package://agvs_description/meshes/motor_wheel.dae" scale="1.0 1.0 1.0"/>
      </geometry>
      <material name="grey">
        <color rgba="0.5 0.5 0.5 1"/>
      </material>
    </visual>
    <collision>
      <origin rpy="0 0 0" xyz="0 0 0"/>
      <geometry>
        <mesh filename="package://agvs_description/meshes/motor_wheel.dae" scale="1.0 1.0 1.0"/>
      </geometry>
    </collision>
  </link>
  <joint name="joint_front_motor_wheel" type="continuous">
    <parent link="base_link"/>
    <child link="front_motor_wheel"/>
    <origin rpy="0 0 0" xyz="0.479 0.0 0.11"/>
    <axis rpy="0 0 0" xyz="0 0 1"/>
    <limit effort="100.0" velocity="100.0"/>
    <joint_properties damping="0.0" friction="{wheel_joint_friction}"/>
  </joint>
  <transmission name="joint_fmw_trans">
    <type>transmission_interface/SimpleTransmission</type>
    <joint name="joint_front_motor_wheel"/>
    <actuator name="joint_fmw_motor">
      <hardwareInterface>EffortJointInterface</hardwareInterface>
      <!-- hardwareInterface>VelocityJointInterface</hardwareInterface -->
      <mechanicalReduction>1.0</mechanicalReduction>
      <!-- motorTorqueConstant>1</motorTorqueConstant -->
    </actuator>
  </transmission>
  <!-- FRONT WHEEL (GREY) -->
  <link name="front_wheel">
    <inertial>
      <mass value="1.250"/>
      <origin xyz="0 0 0"/>
      <inertia ixx="0.0109375" ixy="0.0" ixz="0.0" iyy="0.021125" iyz="0.0" izz="0.0109375"/>
    </inertial>
    <visual>
      <origin rpy="0 0 0" xyz="0 0 0"/>
      <geometry>
        <mesh filename="package://agvs_description/meshes/agvs_wheel.dae" scale="1.0 1.0 1.0"/>
      </geometry>
      <material name="grey">
        <color rgba="0.5 0.5 0.5 1"/>
      </material>
    </visual>
    <collision>
      <origin rpy="0 0 0" xyz="0 0 0"/>
      <geometry>
        <mesh filename="package://agvs_description/meshes/agvs_wheel.dae" scale="1.0 1.0 1.0"/>
      </geometry>
    </collision>
  </link>
  <joint name="joint_front_wheel" type="continuous">
    <parent link="front_motor_wheel"/>
    <child link="front_wheel"/>
    <origin rpy="0 0 3.1416" xyz="0 0 0"/>
    <axis rpy="0 0 0" xyz="0 1 0"/>
    <limit effort="100.0" velocity="100.0"/>
    <joint_properties damping="0.0" friction="{wheel_joint_friction}"/>
  </joint>
  <transmission name="joint_fw_trans">
    <type>transmission_interface/SimpleTransmission</type>
    <joint name="joint_front_wheel"/>
    <actuator name="joint_fw_motor">
      <hardwareInterface>EffortJointInterface</hardwareInterface>
      <mechanicalReduction>1.0</mechanicalReduction>
    </actuator>
  </transmission>
  <!-- SIDE WHEEL LEFT (GREY) -->
  <link name="side_wheel_left">
    <inertial>
      <mass value="1.250"/>
      <origin xyz="0 0 0"/>
      <inertia ixx="0.0109375" ixy="0.0" ixz="0.0" iyy="0.021125" iyz="0.0" izz="0.0109375"/>
    </inertial>
    <visual>
      <origin rpy="0 0 0" xyz="0 0 0"/>
      <geometry>
        <mesh filename="package://agvs_description/meshes/side_wheel_agvs.dae" scale="1.0 1.0 1.0"/>
      </geometry>
      <material name="grey">
        <color rgba="0.5 0.5 0.5 1"/>
      </material>
    </visual>
    <collision>
      <origin rpy="0 0 0" xyz="0 0 0"/>
      <geometry>
        <mesh filename="package://agvs_description/meshes/side_wheel_agvs.dae" scale="1.0 1.0 1.0"/>
      </geometry>
    </collision>
  </link>
  <joint name="joint_side_wheel_left" type="continuous">
    <parent link="base_link"/>
    <child link="side_wheel_left"/>
    <origin rpy="0 0 0" xyz="0 0.267 0.07"/>
    <axis rpy="0 0 0" xyz="0 1 0"/>
    <limit effort="100.0" velocity="100.0"/>
    <joint_properties damping="0.0" friction="{wheel_joint_friction}"/>
  </joint>
  <!-- transmission name="joint_swl_trans">
	 <type>transmission_interface/SimpleTransmission</type>
     <joint name="joint_side_wheel_left" />     
     <actuator name="joint_bw_motor">
	   <hardwareInterface>EffortJointInterface</hardwareInterface>
       <mechanicalReduction>${wheel_mechanical_reduction}</mechanicalReduction>
     </actuator>
  </transmission -->
  <!-- SIDE WHEEL RIGHT (GREY) -->
  <link name="side_wheel_right">
    <inertial>
      <mass value="1.250"/>
      <origin xyz="0 0 0"/>
      <inertia ixx="0.0109375" ixy="0.0" ixz="0.0" iyy="0.021125" iyz="0.0" izz="0.0109375"/>
    </inertial>
    <visual>
      <origin rpy="0 0 0" xyz="0 0 0"/>
      <geometry>
        <mesh filename="package://agvs_description/meshes/side_wheel_agvs.dae" scale="1.0 1.0 1.0"/>
      </geometry>
      <material name="grey">
        <color rgba="0.5 0.5 0.5 1"/>
      </material>
    </visual>
    <collision>
      <origin rpy="0 0 0" xyz="0 0 0"/>
      <geometry>
        <mesh filename="package://agvs_description/meshes/side_wheel_agvs.dae" scale="1.0 1.0 1.0"/>
      </geometry>
    </collision>
  </link>
  <joint name="joint_side_wheel_right" type="continuous">
    <parent link="base_link"/>
    <child link="side_wheel_right"/>
    <origin rpy="0 0 0" xyz="0 -0.267 0.07"/>
    <axis rpy="0 0 0" xyz="0 1 0"/>
    <limit effort="100.0" velocity="100.0"/>
    <joint_properties damping="0.0" friction="{wheel_joint_friction}"/>
  </joint>
  <!-- SICK SENSORS -->
  <!-- Sick Laser Front -->
  <joint name="joint_laser_front" type="fixed">
    <axis xyz="0 1 0"/>
    <origin xyz="0.772 0.0 0.140"/>
    <parent link="base_link"/>
    <child link="laser_front"/>
  </joint>
  <link name="laser_front">
  </link>
  <!-- Sick Laser Back -->
  <joint name="joint_laser_back" type="fixed">
    <axis xyz="0 1 0"/>
    <origin rpy="0 0 3.1416" xyz="-0.772 0.0 0.140"/>
    <parent link="base_link"/>
    <child link="laser_back"/>
  </joint>
  <link name="laser_back">
  </link>
  <!-- IMU SENSOR -->
  <joint name="imu_joint" type="fixed">
    <axis xyz="1 0 0"/>
    <!-- 0 1 0 -->
    <origin xyz="0 0 0.2825"/>
    <parent link="base_link"/>
    <child link="imu_link"/>
  </joint>
  <link name="imu_link">
    <inertial>
      <mass value="0.001"/>
      <origin rpy="0 0 0" xyz="0 0 0"/>
      <inertia ixx="0.0001" ixy="0" ixz="0" iyy="0.000001" iyz="0" izz="0.0001"/>
    </inertial>
    <visual>
      <origin rpy="0 0 0" xyz="0 0 0"/>
      <geometry>
        <box size="0.001 0.001 0.001"/>
      </geometry>
    </visual>
    <collision>
      <origin rpy="0 0 0" xyz="0 0 0"/>
      <geometry>
        <box size=".001 .001 .001"/>
      </geometry>
    </collision>
  </link>
</robot>

