<?xml version="1.0" ?>
<!-- =================================================================================== -->
<!-- |    This document was autogenerated by xacro from agvs_vrep.urdf.xacro           | -->
<!-- |    EDITING THIS FILE BY HAND IS NOT RECOMMENDED                                 | -->
<!-- =================================================================================== -->
<robot name="agvs" xmlns:xacro="http://www.ros.org/wiki/xacro">
  <!-- Robot mechanical and motor parameters -->
  <!-- x,y,z in base_footprint CS -->
  <!-- xacro:property name="side_wheel_offset_z" value="0.075" / -->
  <!-- BASE FOOTPRINT -->
  <!-- base_footprint is a fictitious link(frame) that is on the ground right below base_link origin,
             navigation stack depends on this frame -->
  <link name="base_footprint">
    <visual>
      <origin rpy="0 0 0" xyz="0 0 0"/>
      <geometry>
        <box size="0.001 0.001 0.001"/>
      </geometry>
    </visual>
  </link>
  <joint name="base_footprint_joint" type="fixed">
    <origin rpy="0 0 0" xyz="0 0 -0.005"/>
    <parent link="base_footprint"/>
    <child link="base_link"/>
  </joint>
  <!-- BASE_LINK (RED) -->
  <link name="base_link">
    <inertial>
      <!-- mass value="25.0" />
      <origin xyz="0 0 0" />
      <inertia  ixx="1.391" ixy="0.004"  ixz="0.0"  iyy="6.853"  iyz="0.0"  izz="6.125" / -->
      <mass value="225.0"/>
      <origin xyz="0 0 0"/>
      <inertia ixx="5.0" ixy="0.0" ixz="0.0" iyy="5.0" iyz="0.0" izz="5.0"/>
    </inertial>
    <visual>
      <origin rpy="0 0 0" xyz="0 0 0"/>
      <geometry>
        <mesh filename="package://meshes/chassis_agvs.dae"/>
      </geometry>
      <material name="red">
        <color rgba="0.5 0.1 0.1 1"/>
      </material>
    </visual>
    <collision>
      <origin rpy="0 0 0 " xyz="0 0 0"/>
      <geometry>
        <mesh filename="package://meshes/chassis_agvs.dae"/>
      </geometry>
    </collision>
  </link>
  <!-- BACK MOTOR WHEEL (GREY) -->
  <link name="back_motor_wheel">
    <inertial>
      <mass value="10"/>
      <origin xyz="0 0 0"/>
      <inertia ixx="0.01" ixy="0.0" ixz="0.0" iyy="0.01" iyz="0.0" izz="0.01"/>
    </inertial>
    <visual>
      <origin rpy="0 0 0" xyz="0 0 0"/>
      <geometry>
        <mesh filename="package://meshes/motor_wheel.dae" scale="1.0 1.0 1.0"/>
      </geometry>
      <material name="grey">
        <color rgba="0.5 0.5 0.5 1"/>
      </material>
    </visual>
    <collision>
      <origin rpy="0 0 0" xyz="0 0 0"/>
      <geometry>
        <mesh filename="package://meshes/motor_wheel.dae" scale="1.0 1.0 1.0"/>
      </geometry>
    </collision>
  </link>
  <joint name="joint_back_motor_wheel" type="continuous">
    <parent link="base_link"/>
    <child link="back_motor_wheel"/>
    <origin rpy="0 0 0" xyz="-0.479 0.0 0.11"/>
    <axis rpy="0 0 0" xyz="0 0 1"/>
    <limit effort="100.0" lower="-1.5708" upper="1.5708" velocity="100.0"/>
    <joint_properties damping="2.0" friction="{steer_joint_friction}"/>
  </joint>
  <transmission name="joint_bmw_trans">
    <type>transmission_interface/SimpleTransmission</type>
    <joint name="joint_back_motor_wheel"/>
    <actuator name="joint_bmw_motor">
      <hardwareInterface>EffortJointInterface</hardwareInterface>
      <mechanicalReduction>100.0</mechanicalReduction>
    </actuator>
  </transmission>
  <!-- BACK WHEEL (GREY) -->
  <link name="back_wheel">
    <inertial>
      <mass value="1.250"/>
      <origin xyz="0 0 0"/>
      <inertia ixx="0.0109375" ixy="0.0" ixz="0.0" iyy="0.021125" iyz="0.0" izz="0.0109375"/>
    </inertial>
    <visual>
      <origin rpy="0 0 0" xyz="0 0 0"/>
      <geometry>
        <mesh filename="package://meshes/agvs_wheel.dae" scale="1.0 1.0 1.0"/>
      </geometry>
      <material name="grey">
        <color rgba="0.5 0.5 0.5 1"/>
      </material>
    </visual>
    <collision>
      <origin rpy="0 0 0" xyz="0 0 0"/>
      <geometry>
        <mesh filename="package://meshes/agvs_wheel.dae" scale="1.0 1.0 1.0"/>
      </geometry>
    </collision>
  </link>
  <joint name="joint_back_wheel" type="continuous">
    <parent link="back_motor_wheel"/>
    <child link="back_wheel"/>
    <origin rpy="0 0 3.1416" xyz="0 0 0"/>
    <axis rpy="0 0 0" xyz="0 1 0"/>
    <limit effort="1000.0" velocity="2000.0"/>
    <joint_properties damping="1.0" friction="{wheel_joint_friction}"/>
  </joint>
  <transmission name="joint_bw_trans">
    <type>transmission_interface/SimpleTransmission</type>
    <joint name="joint_back_wheel"/>
    <actuator name="joint_bw_motor">
      <!-- hardwareInterface>EffortJointInterface</hardwareInterface -->
      <hardwareInterface>VelocityJointInterface</hardwareInterface>
      <mechanicalReduction>1.0</mechanicalReduction>
    </actuator>
  </transmission>
  <!-- FRONT MOTOR WHEEL (GREY) -->
  <link name="front_motor_wheel">
    <inertial>
      <mass value="10.0"/>
      <origin xyz="0 0 0"/>
      <inertia ixx="0.01" ixy="0.0" ixz="0.0" iyy="0.01" iyz="0.0" izz="0.01"/>
    </inertial>
    <visual>
      <origin rpy="0 0 0" xyz="0 0 0"/>
      <geometry>
        <mesh filename="package://meshes/motor_wheel.dae" scale="1.0 1.0 1.0"/>
      </geometry>
      <material name="grey">
        <color rgba="0.5 0.5 0.5 1"/>
      </material>
    </visual>
    <collision>
      <origin rpy="0 0 0" xyz="0 0 0"/>
      <geometry>
        <mesh filename="package://meshes/motor_wheel.dae" scale="1.0 1.0 1.0"/>
      </geometry>
    </collision>
  </link>
  <joint name="joint_front_motor_wheel" type="continuous">
    <parent link="base_link"/>
    <child link="front_motor_wheel"/>
    <origin rpy="0 0 0" xyz="0.479 0.0 0.11"/>
    <axis rpy="0 0 0" xyz="0 0 1"/>
    <limit effort="100.0" lower="-1.5708" upper="1.5708" velocity="100.0"/>
    <joint_properties damping="2.0" friction="{steer_joint_friction}"/>
  </joint>
  <transmission name="joint_fmw_trans">
    <type>transmission_interface/SimpleTransmission</type>
    <joint name="joint_front_motor_wheel"/>
    <actuator name="joint_fmw_motor">
      <hardwareInterface>EffortJointInterface</hardwareInterface>
      <mechanicalReduction>100.0</mechanicalReduction>
      <!-- motorTorqueConstant>1</motorTorqueConstant -->
    </actuator>
  </transmission>
  <!-- FRONT WHEEL (GREY) -->
  <link name="front_wheel">
    <inertial>
      <mass value="1.250"/>
      <origin xyz="0 0 0"/>
      <inertia ixx="0.0109375" ixy="0.0" ixz="0.0" iyy="0.021125" iyz="0.0" izz="0.0109375"/>
    </inertial>
    <visual>
      <origin rpy="0 0 0" xyz="0 0 0"/>
      <geometry>
        <mesh filename="package://meshes/agvs_wheel.dae" scale="1.0 1.0 1.0"/>
      </geometry>
      <material name="grey">
        <color rgba="0.5 0.5 0.5 1"/>
      </material>
    </visual>
    <collision>
      <origin rpy="0 0 0" xyz="0 0 0"/>
      <geometry>
        <mesh filename="package://meshes/agvs_wheel.dae" scale="1.0 1.0 1.0"/>
      </geometry>
    </collision>
  </link>
  <joint name="joint_front_wheel" type="continuous">
    <parent link="front_motor_wheel"/>
    <child link="front_wheel"/>
    <origin rpy="0 0 3.1416" xyz="0 0 0"/>
    <axis rpy="0 0 0" xyz="0 1 0"/>
    <limit effort="1000.0" velocity="2000.0"/>
    <joint_properties damping="1.0" friction="{wheel_joint_friction}"/>
  </joint>
  <transmission name="joint_fw_trans">
    <type>transmission_interface/SimpleTransmission</type>
    <joint name="joint_front_wheel"/>
    <actuator name="joint_fw_motor">
      <!-- hardwareInterface>EffortJointInterface</hardwareInterface -->
      <hardwareInterface>VelocityJointInterface</hardwareInterface>
      <mechanicalReduction>1.0</mechanicalReduction>
    </actuator>
  </transmission>
  <!-- SIDE WHEEL LEFT (GREY) -->
  <link name="side_wheel_left">
    <inertial>
      <mass value="1.250"/>
      <origin xyz="0 0 0"/>
      <inertia ixx="0.0109375" ixy="0.0" ixz="0.0" iyy="0.021125" iyz="0.0" izz="0.0109375"/>
    </inertial>
    <visual>
      <origin rpy="0 0 0" xyz="0 0 0"/>
      <geometry>
        <mesh filename="package://meshes/side_wheel_agvs.dae" scale="1.0 1.0 1.0"/>
      </geometry>
      <material name="grey">
        <color rgba="0.5 0.5 0.5 1"/>
      </material>
    </visual>
    <collision>
      <origin rpy="0 0 0" xyz="0 0 0"/>
      <geometry>
        <mesh filename="package://meshes/side_wheel_agvs.dae" scale="1.0 1.0 1.0"/>
      </geometry>
    </collision>
  </link>
  <joint name="joint_side_wheel_left" type="continuous">
    <parent link="base_link"/>
    <child link="side_wheel_left"/>
    <origin rpy="0 0 0" xyz="0 0.267 0.07"/>
    <axis rpy="0 0 0" xyz="0 1 0"/>
    <limit effort="1000.0" velocity="2000.0"/>
    <joint_properties damping="1.0" friction="{side_wheel_joint_friction}"/>
  </joint>
  <transmission name="joint_swl_trans">
    <type>transmission_interface/SimpleTransmission</type>
    <joint name="joint_side_wheel_left"/>
    <actuator name="joint_swl_motor">
      <hardwareInterface>EffortJointInterface</hardwareInterface>
      <mechanicalReduction>1.0</mechanicalReduction>
    </actuator>
  </transmission>
  <!-- SIDE WHEEL RIGHT (GREY) -->
  <link name="side_wheel_right">
    <inertial>
      <mass value="1.250"/>
      <origin xyz="0 0 0"/>
      <inertia ixx="0.0109375" ixy="0.0" ixz="0.0" iyy="0.021125" iyz="0.0" izz="0.0109375"/>
    </inertial>
    <visual>
      <origin rpy="0 0 0" xyz="0 0 0"/>
      <geometry>
        <mesh filename="package://meshes/side_wheel_agvs.dae" scale="1.0 1.0 1.0"/>
      </geometry>
      <material name="grey">
        <color rgba="0.5 0.5 0.5 1"/>
      </material>
    </visual>
    <collision>
      <origin rpy="0 0 0" xyz="0 0 0"/>
      <geometry>
        <mesh filename="package://meshes/side_wheel_agvs.dae" scale="1.0 1.0 1.0"/>
      </geometry>
    </collision>
  </link>
  <joint name="joint_side_wheel_right" type="continuous">
    <parent link="base_link"/>
    <child link="side_wheel_right"/>
    <origin rpy="0 0 0" xyz="0 -0.267 0.07"/>
    <axis rpy="0 0 0" xyz="0 1 0"/>
    <limit effort="1000.0" velocity="2000.0"/>
    <joint_properties damping="1.0" friction="{side_wheel_joint_friction}"/>
  </joint>
  <transmission name="joint_swr_trans">
    <type>transmission_interface/SimpleTransmission</type>
    <joint name="joint_side_wheel_right"/>
    <actuator name="joint_swr_motor">
      <hardwareInterface>EffortJointInterface</hardwareInterface>
      <mechanicalReduction>1.0</mechanicalReduction>
    </actuator>
  </transmission>
  <!-- ***************************** -->
  <link name="elevator_link">
    <inertial>
      <mass value="20.0"/>
      <origin xyz="0 0 0"/>
      <inertia ixx="0.2185" ixy="0.0" ixz="-0.001" iyy="0.33677" iyz="0.0" izz="0.20511"/>
    </inertial>
    <visual>
      <origin rpy="0 0 0" xyz="0 0 0"/>
      <geometry>
        <mesh filename="package://meshes/agvs_top.dae"/>
      </geometry>
    </visual>
    <collision>
      <origin rpy="0 0 0 " xyz="0 0 0"/>
      <geometry>
        <mesh filename="package://meshes/agvs_top.dae"/>
      </geometry>
    </collision>
  </link>
  <joint name="elevator_joint" type="prismatic">
    <parent link="base_link"/>
    <child link="elevator_link"/>
    <limit effort="5000.0" lower="0.0" upper="0.050" velocity="0.25"/>
    <origin rpy="0 0 0" xyz="0 0 0"/>
    <axis xyz="0 0 1"/>
  </joint>
  <transmission name="joint_elevator_trans">
    <type>transmission_interface/SimpleTransmission</type>
    <joint name="elevator_joint"/>
    <actuator name="elevator_motor">
      <hardwareInterface>EffortJointInterface</hardwareInterface>
      <mechanicalReduction>100.0</mechanicalReduction>
    </actuator>
  </transmission>
  <!-- SICK SENSORS -->
  <!-- Sick Laser Front -->
  <joint name="joint_laser_front" type="fixed">
    <axis xyz="0 1 0"/>
    <origin xyz="0.772 0.0 0.140"/>
    <parent link="base_link"/>
    <child link="laser_front"/>
  </joint>
  <link name="laser_front">
  </link>
  <!-- Sick Laser Back -->
  <joint name="joint_laser_back" type="fixed">
    <axis xyz="0 1 0"/>
    <origin rpy="0 0 3.1416" xyz="-0.772 0.0 0.140"/>
    <parent link="base_link"/>
    <child link="laser_back"/>
  </joint>
  <link name="laser_back">
  </link>
  <!-- IMU SENSOR -->
  <joint name="imu_joint" type="fixed">
    <axis xyz="1 0 0"/>
    <!-- 0 1 0 -->
    <origin xyz="0 0 0.2825"/>
    <parent link="base_link"/>
    <child link="imu_link"/>
  </joint>
  <link name="imu_link">
    <inertial>
      <mass value="0.001"/>
      <origin rpy="0 0 0" xyz="0 0 0"/>
      <inertia ixx="0.0001" ixy="0" ixz="0" iyy="0.000001" iyz="0" izz="0.0001"/>
    </inertial>
    <visual>
      <origin rpy="0 0 0" xyz="0 0 0"/>
      <geometry>
        <box size="0.001 0.001 0.001"/>
      </geometry>
    </visual>
    <collision>
      <origin rpy="0 0 0" xyz="0 0 0"/>
      <geometry>
        <box size=".001 .001 .001"/>
      </geometry>
    </collision>
  </link>
</robot>

